<?xml version="1.0"?>
<robot name="ROBOT_PROJECT_VERSION_02" xmlns:xacro="http://ros.org/wiki/xacro">
  
  <xacro:property name="mass" value="1.0"/>
  <xacro:property name="inertia" value="0.166667"/>
  
  <xacro:macro name="inertia_block" params="ixx ixy ixz iyy iyz izz">
    <inertia ixx="${ixx}" ixy="${ixy}" ixz="${ixz}" iyy="${iyy}" iyz="${iyz}" izz="${izz}"/>
  </xacro:macro>
  
  <link name="link_0">
    <inertial>
      <mass>${mass}</mass>
      <origin xyz="0 0 0" rpy="0 0 0"/>
      <xacro:inertia_block ixx="${inertia}" ixy="0" ixz="0" iyy="${inertia}" iyz="0" izz="${inertia}"/>
    </inertial>
    <visual>
      <origin xyz="0 0 0" rpy="0 0 0"/>
      <geometry>
        <mesh filename="package://ROBOT_PROJECT_02_ws/BODY_PART_Version3.dae" scale="1 1 1"/>
      </geometry>
    </visual>
    <collision>
      <origin xyz="0 0 0" rpy="0 0 0"/>
      <geometry>
        <mesh filename="package://ROBOT_PROJECT_02_ws/BODY_PART_Version3.dae" scale="1 1 1"/>
      </geometry>
    </collision>
  </link>
  
  <xacro:macro name="wheel_link" params="link_name mesh_file">
    <link name="${link_name}">
      <inertial>
        <mass>${mass}</mass>
        <origin xyz="0 0 0" rpy="0 0 0"/>
        <xacro:inertia_block ixx="${inertia}" ixy="0" ixz="0" iyy="${inertia}" iyz="0" izz="${inertia}"/>
      </inertial>
      <visual>
        <origin xyz="0 0 0" rpy="0 0 0"/>
        <geometry>
          <mesh filename="package://${mesh_file}" scale="1 1 1"/>
        </geometry>
      </visual>
      <collision>
        <origin xyz="0 0 0" rpy="0 0 0"/>
        <geometry>
          <mesh filename="package://${mesh_file}" scale="1 1 1"/>
        </geometry>
      </collision>
    </link>
  </xacro:macro>
  
  <xacro:wheel_link link_name="link_14" mesh_file="ROBOT_PROJECT_02_ws/Wheel_partV3.dae"/>
  <xacro:wheel_link link_name="link_15" mesh_file="ROBOT_PROJECT_02_ws/Wheel_partV3.dae"/>
  <xacro:wheel_link link_name="link_16" mesh_file="ROBOT_PROJECT_02_ws/Wheel_partV3.dae"/>
  <xacro:wheel_link link_name="link_18" mesh_file="ROBOT_PROJECT_02_ws/Wheel_partV3.dae"/>
  
  <joint name="link_0_JOINT_9" type="revolute">
    <parent link="link_0"/>
    <child link="link_14"/>
    <origin xyz="0 0 0" rpy="0 0 0"/>
    <axis xyz="0 1 0"/>
    <limit lower="-3.14" upper="3.14" effort="-1" velocity="-1"/>
  </joint>
  <joint name="link_0_JOINT_7" type="revolute">
    <parent link="link_0"/>
    <child link="link_15"/>
    <origin xyz="0 0 0" rpy="0 0 0"/>
    <axis xyz="0 1 0"/>
    <limit lower="-3.14" upper="3.14" effort="-1" velocity="-1"/>
  </joint>
  <joint name="link_0_JOINT_6" type="revolute">
    <parent link="link_0"/>
    <child link="link_16"/>
    <origin xyz="0 0 0" rpy="0 0 0"/>
    <axis xyz="0 1 0"/>
    <limit lower="-3.14" upper="3.14" effort="-1" velocity="-1"/>
  </joint>
  <joint name="link_0_JOINT_8" type="revolute">
    <parent link="link_0"/>
    <child link="link_18"/>
    <origin xyz="0 0 0" rpy="0 0 0"/>
    <axis xyz="0 1 0"/>
    <limit lower="-3.14" upper="3.14" effort="-1" velocity="-1"/>
  </joint>
  
</robot>